
================================================================================
Task 11/183: A train travels 120 miles in 2 hours, then slows down and travels 80 miles in 1.5 hours. What is its average speed for the entire journey?
Category: Mathematics & Quantitative Reasoning | Type: word-problems | Difficulty: medium
================================================================================

╭─────────────────────────────────────────────────────────────────────────────────── New run ───────────────────────────────────────────────────────────────────────────────────╮
│                                                                                                                                                                               │
│ A train travels 120 miles in 2 hours, then slows down and travels 80 miles in 1.5 hours. What is its average speed for the entire journey?                                    │
│                                                                                                                                                                               │
╰─ LiteLLMModel - ollama_chat/qwen2.5:1.5b ─────────────────────────────────────────────────────────────────────────────────────────────────────────────────────────────────────╯
━━━━━━━━━━━━━━━━━━━━━━━━━━━━━━━━━━━━━━━━━━━━━━━━━━━━━━━━━━━━━━━━━━━━━━━━━━━━━━━━━━━━ Step 1 ━━━━━━━━━━━━━━━━━━━━━━━━━━━━━━━━━━━━━━━━━━━━━━━━━━━━━━━━━━━━━━━━━━━━━━━━━━━━━━━━━━━━━

Give Feedback / Get Help: https://github.com/BerriAI/litellm/issues/new
LiteLLM.Info: If you need to debug this error, use `litellm._turn_on_debug()'.

Error in generating model output:
litellm.APIConnectionError: Ollama_chatException - [Errno 111\] Connection refused
[Step 1: Duration 0.02 seconds]

ERROR: Error in generating model output:
litellm.APIConnectionError: Ollama_chatException - [Errno 111] Connection refused

Traceback (most recent call last):
  File "/root/agent-evaluation/myenv/lib/python3.12/site-packages/httpx/_transports/default.py", line 101, in map_httpcore_exceptions
    yield
  File "/root/agent-evaluation/myenv/lib/python3.12/site-packages/httpx/_transports/default.py", line 250, in handle_request
    resp = self._pool.handle_request(req)
           ^^^^^^^^^^^^^^^^^^^^^^^^^^^^^^
  File "/root/agent-evaluation/myenv/lib/python3.12/site-packages/httpcore/_sync/connection_pool.py", line 256, in handle_request
    raise exc from None
  File "/root/agent-evaluation/myenv/lib/python3.12/site-packages/httpcore/_sync/connection_pool.py", line 236, in handle_request
    response = connection.handle_request(
               ^^^^^^^^^^^^^^^^^^^^^^^^^^
  File "/root/agent-evaluation/myenv/lib/python3.12/site-packages/httpcore/_sync/connection.py", line 101, in handle_request
    raise exc
  File "/root/agent-evaluation/myenv/lib/python3.12/site-packages/httpcore/_sync/connection.py", line 78, in handle_request
    stream = self._connect(request)
             ^^^^^^^^^^^^^^^^^^^^^^
  File "/root/agent-evaluation/myenv/lib/python3.12/site-packages/httpcore/_sync/connection.py", line 124, in _connect
    stream = self._network_backend.connect_tcp(**kwargs)
             ^^^^^^^^^^^^^^^^^^^^^^^^^^^^^^^^^^^^^^^^^^^
  File "/root/agent-evaluation/myenv/lib/python3.12/site-packages/httpcore/_backends/sync.py", line 207, in connect_tcp
    with map_exceptions(exc_map):
  File "/usr/lib/python3.12/contextlib.py", line 158, in __exit__
    self.gen.throw(value)
  File "/root/agent-evaluation/myenv/lib/python3.12/site-packages/httpcore/_exceptions.py", line 14, in map_exceptions
    raise to_exc(exc) from exc
httpcore.ConnectError: [Errno 111] Connection refused

The above exception was the direct cause of the following exception:

Traceback (most recent call last):
  File "/root/agent-evaluation/myenv/lib/python3.12/site-packages/litellm/main.py", line 2962, in completion
    generator = ollama_chat.get_ollama_response(
                ^^^^^^^^^^^^^^^^^^^^^^^^^^^^^^^^
  File "/root/agent-evaluation/myenv/lib/python3.12/site-packages/litellm/llms/ollama_chat.py", line 330, in get_ollama_response
    response = sync_client.post(
               ^^^^^^^^^^^^^^^^^
  File "/root/agent-evaluation/myenv/lib/python3.12/site-packages/litellm/llms/custom_httpx/http_handler.py", line 709, in post
    raise e
  File "/root/agent-evaluation/myenv/lib/python3.12/site-packages/litellm/llms/custom_httpx/http_handler.py", line 688, in post
    response = self.client.send(req, stream=stream)
               ^^^^^^^^^^^^^^^^^^^^^^^^^^^^^^^^^^^^
  File "/root/agent-evaluation/myenv/lib/python3.12/site-packages/httpx/_client.py", line 914, in send
    response = self._send_handling_auth(
               ^^^^^^^^^^^^^^^^^^^^^^^^^
  File "/root/agent-evaluation/myenv/lib/python3.12/site-packages/httpx/_client.py", line 942, in _send_handling_auth
    response = self._send_handling_redirects(
               ^^^^^^^^^^^^^^^^^^^^^^^^^^^^^^
  File "/root/agent-evaluation/myenv/lib/python3.12/site-packages/httpx/_client.py", line 979, in _send_handling_redirects
    response = self._send_single_request(request)
               ^^^^^^^^^^^^^^^^^^^^^^^^^^^^^^^^^^
  File "/root/agent-evaluation/myenv/lib/python3.12/site-packages/httpx/_client.py", line 1014, in _send_single_request
    response = transport.handle_request(request)
               ^^^^^^^^^^^^^^^^^^^^^^^^^^^^^^^^^
  File "/root/agent-evaluation/myenv/lib/python3.12/site-packages/httpx/_transports/default.py", line 249, in handle_request
    with map_httpcore_exceptions():
  File "/usr/lib/python3.12/contextlib.py", line 158, in __exit__
    self.gen.throw(value)
  File "/root/agent-evaluation/myenv/lib/python3.12/site-packages/httpx/_transports/default.py", line 118, in map_httpcore_exceptions
    raise mapped_exc(message) from exc
httpx.ConnectError: [Errno 111] Connection refused

During handling of the above exception, another exception occurred:

Traceback (most recent call last):
  File "/root/agent-evaluation/myenv/lib/python3.12/site-packages/smolagents/agents.py", line 1496, in _step_stream
    chat_message: ChatMessage = self.model.generate(
                                ^^^^^^^^^^^^^^^^^^^^
  File "/root/agent-evaluation/myenv/lib/python3.12/site-packages/smolagents/models.py", line 1044, in generate
    response = self.client.completion(**completion_kwargs)
               ^^^^^^^^^^^^^^^^^^^^^^^^^^^^^^^^^^^^^^^^^^^
  File "/root/agent-evaluation/myenv/lib/python3.12/site-packages/litellm/utils.py", line 1283, in wrapper
    raise e
  File "/root/agent-evaluation/myenv/lib/python3.12/site-packages/litellm/utils.py", line 1161, in wrapper
    result = original_function(*args, **kwargs)
             ^^^^^^^^^^^^^^^^^^^^^^^^^^^^^^^^^^
  File "/root/agent-evaluation/myenv/lib/python3.12/site-packages/litellm/main.py", line 3241, in completion
    raise exception_type(
          ^^^^^^^^^^^^^^^
  File "/root/agent-evaluation/myenv/lib/python3.12/site-packages/litellm/litellm_core_utils/exception_mapping_utils.py", line 2239, in exception_type
    raise e
  File "/root/agent-evaluation/myenv/lib/python3.12/site-packages/litellm/litellm_core_utils/exception_mapping_utils.py", line 2208, in exception_type
    raise APIConnectionError(
litellm.exceptions.APIConnectionError: litellm.APIConnectionError: Ollama_chatException - [Errno 111] Connection refused

The above exception was the direct cause of the following exception:

Traceback (most recent call last):
  File "/root/agent-evaluation/loop-mac-mini.py", line 132, in <module>
    output = agent.run(task)
             ^^^^^^^^^^^^^^^
  File "/root/agent-evaluation/myenv/lib/python3.12/site-packages/smolagents/agents.py", line 399, in run
    steps = list(self._run_stream(task=self.task, max_steps=max_steps, images=images))
            ^^^^^^^^^^^^^^^^^^^^^^^^^^^^^^^^^^^^^^^^^^^^^^^^^^^^^^^^^^^^^^^^^^^^^^^^^^
  File "/root/agent-evaluation/myenv/lib/python3.12/site-packages/smolagents/agents.py", line 478, in _run_stream
    raise e
  File "/root/agent-evaluation/myenv/lib/python3.12/site-packages/smolagents/agents.py", line 473, in _run_stream
    for el in self._execute_step(action_step):
  File "/root/agent-evaluation/myenv/lib/python3.12/site-packages/smolagents/agents.py", line 495, in _execute_step
    for el in self._step_stream(memory_step):
  File "/root/agent-evaluation/myenv/lib/python3.12/site-packages/smolagents/agents.py", line 1518, in _step_stream
    raise AgentGenerationError(f"Error in generating model output:\n{e}", self.logger) from e
smolagents.utils.AgentGenerationError: Error in generating model output:
litellm.APIConnectionError: Ollama_chatException - [Errno 111] Connection refused

Task 11 complete.
------------------------------------------------------------
